============================================
Test Run Started: 2025-07-02 13:35:11
--------------------------------------------
============================= test session starts ==============================
platform linux -- Python 3.10.18, pytest-8.3.5, pluggy-1.6.0 -- /opt/hostedtoolcache/Python/3.10.18/x64/bin/python
cachedir: .pytest_cache
metadata: {'Python': '3.10.18', 'Platform': 'Linux-6.11.0-1015-azure-x86_64-with-glibc2.39', 'Packages': {'pytest': '8.3.5', 'pluggy': '1.6.0'}, 'Plugins': {'metadata': '3.1.1', 'rerunfailures': '15.1', 'html': '4.1.1', 'Faker': '37.4.0', 'xdist': '3.8.0'}, 'CI': 'true', 'JAVA_HOME': '/usr/lib/jvm/temurin-17-jdk-amd64'}
rootdir: /home/runner/work/Mocha_accounting/Mocha_accounting
plugins: metadata-3.1.1, rerunfailures-15.1, html-4.1.1, Faker-37.4.0, xdist-3.8.0
collecting ... collected 0 items / 1 error

==================================== ERRORS ====================================
_____________________ ERROR collecting tests/test_login.py _____________________
ImportError while importing test module '/home/runner/work/Mocha_accounting/Mocha_accounting/tests/test_login.py'.
Hint: make sure your test modules/packages have valid Python names.
Traceback:
/opt/hostedtoolcache/Python/3.10.18/x64/lib/python3.10/importlib/__init__.py:126: in import_module
    return _bootstrap._gcd_import(name[level:], package, level)
tests/test_login.py:13: in <module>
    from pages.login_page import LoginPage
pages/login_page.py:4: in <module>
    from actions.actions import Actions
actions/actions.py:3: in <module>
    from asyncio import timeout
E   ImportError: cannot import name 'timeout' from 'asyncio' (/opt/hostedtoolcache/Python/3.10.18/x64/lib/python3.10/asyncio/__init__.py)
- Generated html report: file:///home/runner/work/Mocha_accounting/Mocha_accounting/C%3A%5CUsers%5CTaurus13%5CPycharmProjects%5CPythonProject%5Creports/20250702_133512/report.html -
=========================== short test summary info ============================
ERROR tests/test_login.py
!!!!!!!!!!!!!!!!!!!! Interrupted: 1 error during collection !!!!!!!!!!!!!!!!!!!!
=============================== 1 error in 0.15s ===============================
--------------------------------------------
Test Run Finished: 2025-07-02 13:35:12
Duration: 1 seconds
Status: FAILURE
Exit Code: 2
============================================
========== Linting Errors ==========
0
========== End of Linting ==========
============================================
Test Run Started: 2025-07-02 13:56:54
--------------------------------------------
============================= test session starts ==============================
platform linux -- Python 3.10.18, pytest-8.3.5, pluggy-1.6.0 -- /opt/hostedtoolcache/Python/3.10.18/x64/bin/python
cachedir: .pytest_cache
metadata: {'Python': '3.10.18', 'Platform': 'Linux-6.11.0-1015-azure-x86_64-with-glibc2.39', 'Packages': {'pytest': '8.3.5', 'pluggy': '1.6.0'}, 'Plugins': {'metadata': '3.1.1', 'rerunfailures': '15.1', 'html': '4.1.1', 'Faker': '37.4.0', 'xdist': '3.8.0'}, 'CI': 'true', 'JAVA_HOME': '/usr/lib/jvm/temurin-17-jdk-amd64'}
rootdir: /home/runner/work/Mocha_accounting/Mocha_accounting
plugins: metadata-3.1.1, rerunfailures-15.1, html-4.1.1, Faker-37.4.0, xdist-3.8.0
collecting ... collected 0 items / 1 error

==================================== ERRORS ====================================
_____________________ ERROR collecting tests/test_login.py _____________________
ImportError while importing test module '/home/runner/work/Mocha_accounting/Mocha_accounting/tests/test_login.py'.
Hint: make sure your test modules/packages have valid Python names.
Traceback:
/opt/hostedtoolcache/Python/3.10.18/x64/lib/python3.10/importlib/__init__.py:126: in import_module
    return _bootstrap._gcd_import(name[level:], package, level)
tests/test_login.py:13: in <module>
    from pages.login_page import LoginPage
pages/login_page.py:4: in <module>
    from actions.actions import Actions
actions/actions.py:3: in <module>
    from asyncio import timeout
E   ImportError: cannot import name 'timeout' from 'asyncio' (/opt/hostedtoolcache/Python/3.10.18/x64/lib/python3.10/asyncio/__init__.py)
- Generated html report: file:///home/runner/work/Mocha_accounting/Mocha_accounting/C%3A%5CUsers%5CTaurus13%5CPycharmProjects%5CPythonProject%5Creports/20250702_135655/report.html -
=========================== short test summary info ============================
ERROR tests/test_login.py
!!!!!!!!!!!!!!!!!!!! Interrupted: 1 error during collection !!!!!!!!!!!!!!!!!!!!
=============================== 1 error in 0.17s ===============================
--------------------------------------------
Test Run Finished: 2025-07-02 13:56:55
Duration: 1 seconds
Status: FAILURE
Exit Code: 2
============================================
